Workbook

Sheet PARTICULAR
F1: =COUNTA(F3:F96) -> 74
A2: Coluna 1 | B2: . | C2: . 2 | D2: C | E2: Coluna 5 | F2: NOME | G2: FICHA | H2: TURMA | I2: IDADE | J2: NASCIMENTO | K2: CPF | L2: DATA INÍCIO: | M2: DIAS | N2: TELEFONE: | O2: JANEIRO | P2: FEVEREIRO | Q2: MARÇO | R2: ABRIL | S2: MAIO | T2: JUNHO | U2: JULHO | V2: AGOSTO | W2: SETEMBRO | X2: OUTUBRO | Y2: NOVEMBRO | Z2: DEZEMBRO | AA2: VENCIMENTO | AB2: ELETRO | AC2: ATESTADO DE APTIDÃO | AD2: COMPROVANTE DE RESIDÊNCIA | AE2: CARTEIRA DE VACINAÇÃO | AF2: CARTÃO SUS | AG2: BOLETIM | AH2: TIPO SANGUÍNEO | AI2: DADOS FISCAIS | AJ2: ESCOLA | AK2: ENDEREÇO: | AL2: CIDADE | AM2: -
E3: =SUMPRODUCT((AB3:AL3<>"")*(AB3:AL3<>"-")) -> 4 | F3: ÁLVARO RIFFEL COUTO | G3: OK | H3: TURMA 3 (TARDE) | I3: =INT((TODAY()-J3)/365.25) -> 8 | J3: 43167 | L3: 46220 | M3: 4 | N3: 47 991841767 47 996786075 47 989134934 | O3: - | P3: - | Q3: - | R3: - | S3: - | T3: - | U3: 46234 | V3: TRANCOU | W3: 46245 | AA3: 10 | AI3: RAIRA DOMINGUES RIFFEL - 030.871.020-75 - RAIRIFF.27@GMAIL.COM | AJ3: ANTONIO LUCIO | AK3: R. ISRAEL 431 | AL3: BC
E4: =SUMPRODUCT((AB4:AL4<>"")*(AB4:AL4<>"-")) -> 5 | F4: ANTHONY GABRIEL DA SILVA | G4: OK | H4: TURMA 7 (TARDE) | I4: =INT((TODAY()-J4)/365.25) -> 11 | J4: 42267 | K4: 130.396.239-07 | L4: 46237 | M4: 3 | N4: 47 9121-1515 | O4: - | P4: - | Q4: - | R4: - | S4: - | T4: - | U4: - | V4: 46235 | W4: 46269 | AA4: 10 | AH4: O+ | AI4: ANTONIEL ANTONIO DA SILVA - 946.553.329-72 - ANTONIELSILVA@GSM.SILVA.COM.BR | AJ4: VISÃO | AK4: R. GUAMAPARIM, 359 | AL4: CAMBORIU
E5: =SUMPRODUCT((AB5:AL5<>"")*(AB5:AL5<>"-")) -> 7 | F5: ANTÔNIO JACOMETTO NETO | G5: OK | H5: TURMA 7 (TARDE) | I5: =INT((TODAY()-J5)/365.25) -> 7 | J5: 43440 | K5: 146.695.329-28 | L5: 46273 | M5: 2 | N5: 47 9731-7920 | O5: - | P5: - | Q5: - | R5: - | S5: - | T5: - | U5: - | V5: - | W5: 46273 | AA5: 10 | AD5: OK | AF5: UNIMED | AH5: A+ | AI5: LUCIANE GONÇALVES - 031.619.119-11 - LUEMUNHOZ@GMAIL.COM | AJ5: COC | AK5: RUA NEPAL, 289 | AL5: BC
E6: =SUMPRODUCT((AB6:AL6<>"")*(AB6:AL6<>"-")) -> 7 | F6: ANTÔNIO SALVADOR SOARES | G6: OK | H6: TURMA 6 (MANHÃ) | I6: =INT((TODAY()-J6)/365.25) -> 7 | J6: 43638 | K6: 151.647.179-21 | L6: - | M6: 2 | N6: MÃE 47 9615-0551 | O6: - | P6: - | Q6: - | R6: - | S6: - | T6: 46209 | U6: 46244 | V6: 46254 | W6: 46286 | AA6: 25 | AB6: 2026 | AC6: OK | AD6: OK | AE6: OK | AF6: OK | AH6: A- | AI6: ALEX MARCELINO SOARES 082.649.079-46 - ALEXMARCELINOSOARES@GMAIL.COM | AJ6: - | AK6: - | AL6: -
B7: X | E7: =SUMPRODUCT((AB7:AL7<>"")*(AB7:AL7<>"-")) -> 6 | F7: ARTHUR HINCKEL DALLAGNO | G7: OK | H7: TURMA 7 (TARDE) | I7: =INT((TODAY()-J7)/365.25) -> 10 | J7: 42375 | K7: 130.236.229.14 | L7: - | M7: 4 | N7: MÃE: 47 9 9224 1881 PAI: 47 9 9621 9678 | O7: - | P7: 46076 | Q7: 46090 | R7: 46119 | S7: 46147 | T7: 46199 | U7: 46268 | V7: 46275 | W7: 46300 | AA7: 20 | AD7: ok | AE7: OK | AI7: MAICON MEZAVILLA DALLAGNO - 005.676.820-64 - MAICONDALLAGNO@GMAIL.COM | AJ7: TANIA REGINA | AK7: R. GUARAPARIM - N 130, TABULEIRO | AL7: CAMBORIÚ
E8: =SUMPRODUCT((AB8:AL8<>"")*(AB8:AL8<>"-")) -> 6 | F8: ARTHUR LEONARDO SIMAS | G8: OK | H8: TURMA 3 (TARDE) | I8: =INT((TODAY()-J8)/365.25) -> 9 | J8: 42785 | K8: 136.366.614-30 | L8: 46259 | M8: 3 | N8: 47999131305 | O8: - | P8: - | Q8: - | R8: - | S8: - | T8: - | U8: - | V8: 46259 | AA8: 28 | AD8: OK | AG8: 2026 | AI8: ANDERSON L SIMAS - 025.031.329-44 - ANDERSONSIMAS@HOTMAIL.COM | AJ8: ARMANDO CESAR | AK8: R. SAO LUIZ, VILA REAL, 670 | AL8: CAMBOTIÚ
E9: =SUMPRODUCT((AB9:AL9<>"")*(AB9:AL9<>"-")) -> 4 | F9: ARTHUR VALENDORFF DE CARVALHO | G9: OK | H9: TURMA 2 (MANHÃ) | I9: =INT((TODAY()-J9)/365.25) -> 11 | J9: 42146 | L9: 46235 | M9: 4 | N9: MÃE: 4799241881 PAI: 47 9962149678 | O9: - | P9: - | Q9: - | R9: - | S9: - | T9: - | U9: - | V9: - | W9: 46273 | AA9: 10 | AI9: DANIELE APARECIDA VALLENDORFF - 025.969.189-51 - DANIELE_VALENDORFF@HOTMAIL.COM | AJ9: VISÃO | AK9: R. CEREJEIRA - N 383, TABULEIRO | AL9: CAMBORIÚ
E10: =SUMPRODUCT((AB10:AL10<>"")*(AB10:AL10<>"-")) -> 0 | F10: AUGUSTO TESTONI | I10: =INT((TODAY()-J10)/365.25) -> 126
B11: X | E11: =SUMPRODUCT((AB11:AL11<>"")*(AB11:AL11<>"-")) -> 4 | F11: AYLA G. MELLO SHFFNAN | G11: OK | H11: TURMA 3 (TARDE) | I11: =INT((TODAY()-J11)/365.25) -> 6 | J11: 43863 | K11: 154.225.199-06 | L11: 46197 | M11: 2 | N11: MÃE 4796404126 | O11: - | P11: - | Q11: - | R11: - | S11: - | T11: 46197 | U11: 46279 | V11: TRANCOU | W11: 46280 | AA11: 10 | AC11: OK | AD11: OK | AE11: OK | AF11: OK
E12: =SUMPRODUCT((AB12:AL12<>"")*(AB12:AL12<>"-")) -> 0 | F12: BENICIO BUSATTO | H12: TURMA 7 (TARDE) | I12: 12 | L12: - | M12: 2 | N12: 47 9646-5895 | O12: - | P12: - | Q12: - | R12: - | S12: - | T12: - | U12: - | V12: - | W12: 46288 | AI12: -
E13: =SUMPRODUCT((AB13:AL13<>"")*(AB13:AL13<>"-")) -> 2 | F13: BERNARDO DE LIMA LINDNER | H13: TURMA 7 (TARDE) | I13: 12 | J13: 42579 | K13: 146.644.509-23 | L13: 46308 | M13: 2 | N13: 47 9901-5429 | O13: - | P13: - | Q13: - | R13: - | S13: - | T13: - | U13: -- | V13: - | W13: - | X13: 46308 | AA13: 15 | AC13: OK | AH13: O+
B14: X | C14: AGOSTO | E14: =SUMPRODUCT((AB14:AL14<>"")*(AB14:AL14<>"-")) -> 10 | F14: BENJAMIN PIORELLI COSTA | G14: OK | H14: TURMA 3 (TARDE) | I14: =INT((TODAY()-J14)/365.25) -> 9 | J14: 42692 | K14: 137.277.199-90 | L14: 46091 | M14: 3 | N14: 47999425750 47999046645 | O14: - | P14: - | Q14: 46091 | R14: 46183 | S14: 46152 | T14: 46183 | U14: 46213 | V14: 46244 | W14: 46276 | X14: 46276 | Y14: 46276 | Z14: 11/09 + JAN E FEV | AA14: 10 | AB14: 2026 | AC14: OK | AD14: OK | AE14: OK | AF14: OK | AG14: 2026 | AH14: O+ | AI14: - | AJ14: iate club | AK14: RUA COQUEIROS N -70 | AL14: CAMBORIÚ
B15: X | E15: =SUMPRODUCT((AB15:AL15<>"")*(AB15:AL15<>"-")) -> 6 | F15: BENTO GHENO GONÇALVES | G15: OK | H15: TURMA 2 (MANHÃ) | I15: =INT((TODAY()-J15)/365.25) -> 7 | J15: 43509 | K15: 07774625917 | L15: 46058 | M15: 2 | N15: MÃE: 47 9 91230016 PAI: 47 9 9958 4865 | O15: - | P15: 46058 | Q15: 46114 | R15: 46163 | S15: 46194 | T15: 46197 | U15: FERIAS | V15: 46218 | W15: 46247 | AA15: 5 | AD15: OK | AH15: A+ | AI15: ADARA LUZIA GHENO GONÇALVES - 077.746.259-17 - ADARAGHENO@GMAIL.COM | AJ15: ANGLO | AK15: R. 620 - 40, BC | AL15: BC
B16: X | C16: DEZEMBRO | E16: =SUMPRODUCT((AB16:AL16<>"")*(AB16:AL16<>"-")) -> 10 | F16: BERNARDO ROCHA | G16: OK | H16: TURMA 3 (TARDE) | I16: =INT((TODAY()-J16)/365.25) -> 10 | J16: 42514 | K16: 127.114.169-84 | L16: 46166 | M16: 4 | N16: MÃE: 47 9 8422 2164 PAI: 47 9 8467 2537 | O16: 46045 | P16: 46045 | Q16: 46045 | R16: 46045 | S16: 46045 | T16: 46045 | U16: 46045 | V16: 46045 | W16: 46045 | X16: 46045 | Y16: 46045 | Z16: 46045 | AA16: 10 | AB16: 2026 | AD16: OK | AE16: OK | AF16: OK | AG16: 2026 | AH16: B+ | AI16: ROMÁRIO ROCHA SANTOS - 050.426.615-22 - BERNAROMA1005@GMAIL.COM | AJ16: ARTUR SICHMANN | AK16: AV. SANTA CATARINA - 205, CENTRO | AL16: CAMBORIÚ
E17: =SUMPRODUCT((AB17:AL17<>"")*(AB17:AL17<>"-")) -> 4 | F17: BERNARDO BUENO DE ALBURQUERQUE | G17: OK | H17: TURMA 3 (TARDE) | I17: =INT((TODAY()-J17)/365.25) -> 10 | J17: 42476 | K17: 140.857.389-09 | L17: 46303 | M17: 2 | N17: 47999579720 | O17: - | P17: - | Q17: - | R17: - | S17: - | T17: - | U17: - | V17: - | W17: - | X17: 46303 | AA17: 8 | AI17: FERNANDA BUENO - 356.083.688-35 | AJ17: VEREADOR SANTA | AK17: RUA 2000, 955 | AL17: BC
E18: =SUMPRODUCT((AB18:AL18<>"")*(AB18:AL18<>"-")) -> 2 | F18: BRAYAN BELICA DALMOLIN | G18: OK | H18: TURMA 2 (MANHÃ) | I18: =INT((TODAY()-J18)/365.25) -> 9 | J18: 42889 | K18: 133.823.159-63 | L18: 46248 | M18: 1 | N18: 47996425857 47984038891 | O18: - | P18: - | Q18: - | R18: - | S18: - | T18: - | U18: - | V18: 46248 | W18: 46283 | AA18: 15 | AF18: UNIMED | AG18: 2026
E19: =SUMPRODUCT((AB19:AL19<>"")*(AB19:AL19<>"-")) -> 0 | F19: BRENO GABRIEL FERREIRA | H19: TURMA 7 (TARDE) | I19: 9 | L19: 46293 | M19: 3 | N19: 47 9701-7269 | O19: - | P19: - | Q19: - | R19: - | S19: - | T19: - | U19: - | V19: - | W19: 46294
B20: X | D20: x | E20: =SUMPRODUCT((AB20:AL20<>"")*(AB20:AL20<>"-")) -> 10 | F20: CARLOS PYETRO MATOS DE SOUZA | G20: OK | H20: TURMA 7 (TARDE) | I20: =INT((TODAY()-J20)/365.25) -> 12 | J20: 41655 | K20: 148.034.649-79 | L20: - | M20: 2 | N20: MÃE: 47 9 9127 9106 PAI: 47 9 8818 4342 | O20: 46049 | P20: 46097 | Q20: 46136 | R20: 46170 | S20: 46199 | T20: 46220 | U20: 46232 | V20: 46262 | AA20: 27 | AB20: 2026 | AC20: OK | AD20: OK | AE20: OK | AF20: OK | AG20: 2026 | AH20: O+ | AI20: - | AJ20: CAIC | AK20: R. CONCÓRDIA - N 300, MUNICIPIOS | AL20: BC
E21: =SUMPRODUCT((AB21:AL21<>"")*(AB21:AL21<>"-")) -> 7 | F21: CICERO DE CASTRO DAPIEVE | G21: OK | H21: TURMA 2 (MANHÃ) | I21: =INT((TODAY()-J21)/365.25) -> 7 | J21: 43585 | K21: 062.635.560-56 | L21: 46273 | M21: 2 | N21: 55 9720-8363 | O21: - | P21: - | Q21: - | R21: - | S21: - | T21: - | U21: - | V21: - | W21: 46273 | X21: 46308 | AA21: 8 | AE21: OK | AF21: OK | AG21: 2026 | AI21: WAGNER FACCIN DAPIEVE - 030.234.520-59 WAGNERFOCCIN1999@GMAIL.COM | AJ21: EMB DOMINGOS FONSECA | AK21: CEREJEIRA, 181 | AL21: CAMBORIU
E22: =SUMPRODUCT((AB22:AL22<>"")*(AB22:AL22<>"-")) -> 5 | F22: DANIEL ELIAS RODRIGUES SILVA DOS SANTOS | G22: OK | H22: TURMA 3 (TARDE) | I22: =INT((TODAY()-J22)/365.25) -> 6 | J22: 44052 | K22: 156.524.499-00 | L22: 46266 | M22: 2 | N22: 45 9823-3271 | O22: - | P22: - | Q22: - | R22: - | S22: - | T22: - | U22: - | V22: 46258 | W22: 46303 | AA22: 25 | AD22: OK | AI22: EDINEIA NEVES RODRIGUES - 905.745.839-04 | AJ22: CEI NEIDE | AK22: R. JARDIM EUROPA, ST REGINA | AL22: CAMBORIU
E23: =SUMPRODUCT((AB23:AL23<>"")*(AB23:AL23<>"-")) -> 0 | F23: DOM TOAZZA RIGOM | M23: 3 | O23: - | P23: - | Q23: - | R23: - | S23: - | T23: - | U23: - | V23: - | W23: - | X23: 46295
B24: X | E24: =SUMPRODUCT((AB24:AL24<>"")*(AB24:AL24<>"-")) -> 11 | F24: DAVI DE SOUZA SEBEN | G24: OK | H24: TURMA 2 (MANHÃ) | I24: =INT((TODAY()-J24)/365.25) -> 9 | J24: 42697 | K24: 130.002.029-60 | L24: - | M24: 3 | N24: MÃE: 47 9 9117 9866 PAI: 47 9 9763 3129 | O24: 46075 | P24: 46075 | Q24: 46146 | R24: 46146 | S24: 46204 | T24: 46204 | U24: 46280 | V24: 46280 | W24: 46296 | X24: 46308 | AA24: 10 | AB24: 2026 | AC24: OK | AD24: OK | AE24: OK | AF24: OK | AG24: 2026 | AH24: A+ | AI24: ANDRESSA ALVES DE SOUZA SEBEN - 015.458.010-45 - andressa0.7@hotmail.com | AJ24: VEREADOR SANTA | AK24: R. 2870 - N 888, CENTRO | AL24: BC
E25: =SUMPRODUCT((AB25:AL25<>"")*(AB25:AL25<>"-")) -> 3 | F25: DAVI FERREIRA FIDENCIO | G25: OK | H25: TURMA 2 (MANHÃ) | I25: =INT((TODAY()-J25)/365.25) -> 12 | J25: 41676 | K25: 117.863.789-14 | L25: - | M25: 2 | N25: MÃE 4796404126 | O25: - | P25: - | Q25: - | R25: - | S25: - | T25: 46197 | U25: 46279 | V25: TRANCOU | W25: 46280 | AA25: 10 | AC25: OK | AD25: OK | AG25: 2026
B26: X | E26: =SUMPRODUCT((AB26:AL26<>"")*(AB26:AL26<>"-")) -> 8 | F26: DAVI FONSECA BEUTING | G26: OK | H26: TURMA 7 (TARDE) | I26: =INT((TODAY()-J26)/365.25) -> 14 | J26: 40848 | K26: 043.448.749-00 | L26: - | M26: 4 | N26: MÃE: 47 9 9101 9149 | O26: 46049 | P26: 46063 | Q26: 46091 | R26: 46128 | S26: 46153 | T26: 46188 | U26: 46213 | V26: 46252 | W26: 46279 | X26: 46302 | AA26: 10 | AD26: OK | AE26: OK | AF26: OK | AH26: A+ | AI26: ERICA DIETRICH FONSECA - 217.430.709-00 - SIMARAFONSECA@GMAIL.COM | AJ26: IVO SILVEIRA | AK26: R. 1500 - 1830 - BC | AL26: BC
E27: =SUMPRODUCT((AB27:AL27<>"")*(AB27:AL27<>"-")) -> 5 | F27: DAVI GOMES SILVEIRA | G27: OK | H27: TURMA 2 (MANHÃ) | I27: =INT((TODAY()-J27)/365.25) -> 6 | J27: 43855 | K27: 154.128.749-59 | L27: 46212 | M27: 2 | N27: 47 9600-0000 | O27: - | P27: - | Q27: - | R27: - | S27: - | T27: - | U27: 46212 | V27: 46266 | W27: TRANCOU | AA27: 10 | AH27: O+ | AI27: ADRIANO LUZ SILVEIRA - 056.262.799-54 | AJ27: ANGLO | AK27: RUA SASSAFAZ, 835 | AL27: CAMBORIÚ
B28: X | E28: =SUMPRODUCT((AB28:AL28<>"")*(AB28:AL28<>"-")) -> 7 | F28: DAVI MARQUES DA SILVA | G28: OK | H28: TURMA 3 (TARDE) | I28: =INT((TODAY()-J28)/365.25) -> 10 | J28: 42406 | K28: 135.689.799-18 | L28: 2025 | M28: 2 | N28: MÃE: 47 9 9996 2393 PAI: 47 9 9670 9314 | O28: - | P28: - | Q28: - | R28: 46163 | S28: 46163 | T28: 46163 | U28: 46163 | V28: 46163 | W28: 46163 | X28: 46163 | Y28: 46163 | Z28: 46163 | AA28: 5 | AD28: OK | AE28: OK | AF28: OK | AI28: MÁRIO FERNANDO - 981.854.629-68 - mariofernado@hotmail.com | AJ28: ROGÉRIO L. KUHNEN | AK28: R. JERUSALÉM - N 1581, SANTA REGINA | AL28: CAMBORIÚ
B29: X | E29: =SUMPRODUCT((AB29:AL29<>"")*(AB29:AL29<>"-")) -> 5 | F29: EDUARDO PEDRO BOM CORDEIRO | G29: OK | H29: TURMA 3 (TARDE) | I29: =INT((TODAY()-J29)/365.25) -> 11 | J29: 42019 | K29: 119.129.139-17 | L29: - | M29: 2 | N29: MÃE: 41 98784 5809 PAI: 41 98793 8676 | O29: 46045 | P29: 46080 | Q29: 46108 | R29: 46206 | S29: 46147 | T29: 46183 | U29: 46234 | V29: 46268 | AA29: 25 | AD29: ok | AI29: ANDRE RAFAEL CORDEIRO - 052.925.585-55 - | AJ29: VEREADOR SANTA | AK29: R. LEANDRO BERTOLDI - 191, CEDRO | AL29: CAMBORIÚ
B30: X | E30: =SUMPRODUCT((AB30:AL30<>"")*(AB30:AL30<>"-")) -> 9 | F30: EMANUEL SIMAS MACHADO | G30: OK | H30: TURMA 2 (MANHÃ) | I30: =INT((TODAY()-J30)/365.25) -> 11 | J30: 42089 | K30: 13507525925 | L30: - | M30: 3 | N30: MÃE: 47 9 9611 4679 PAI: 47 9 9668 6810 | O30: 46048 | P30: 46087 | Q30: 46119 | R30: 46192 | S30: 46232 | T30: 46240 | U30: 46254 | AA30: 25 | AD30: OK | AE30: OK | AF30: OK | AG30: 2026 | AH30: O+ | AI30: DAIANE CRISTNA PORTO SIMAS - 064.140.549-92 - DAIANE_CAMBORIÚ@HOTMAIL.COM | AJ30: ARTUR SICHMANN | AK30: R. PREFEITO JOSÉ CESARIO PEREIRA - N 158, CENTRO | AL30: CAMBORIÚ
E31: =SUMPRODUCT((AB31:AL31<>"")*(AB31:AL31<>"-")) -> 4 | F31: ENZO TERESKOVAC | G31: OK | H31: TURMA 2 (MANHÃ) | I31: =INT((TODAY()-J31)/365.25) -> 9 | J31: 42947 | K31: 298.136.128-78 | L31: - | M31: 2 | N31: 11 960385894 | O31: - | P31: - | Q31: - | R31: - | S31: - | T31: -- | U31: - | V31: - | W31: 46265 | AA31: 30 | AI31: MARCELO RELVAS TERESKOVAC - 298.136.128-78 - MR.TERESKOVAC@GMAIL.COM | AJ31: FOR LIFE SCHOOL | AK31: RUA GUAMIRIM, 316 | AL31: CAMBORIU
E32: =SUMPRODUCT((AB32:AL32<>"")*(AB32:AL32<>"-")) -> 4 | F32: GABRIEL OSÓRIO GUEDES | G32: OK | H32: TURMA 7 (TARDE) | I32: =INT((TODAY()-J32)/365.25) -> 9 | J32: 42723 | K32: 053.322.370-90 | L32: (MAIO)/2026 | M32: 4 | N32: MÃE: 55 9 8453 4336 | O32: - | P32: - | Q32: - | R32: - | S32: 46163 | T32: 46163 | U32: 46163 | V32: 46240 | W32: 46240 | X32: 46240 | AA32: 5 | AI32: VIRGINIA OSÓRIO - 041.441.270-28 - OSÓRIO.VIRGINIA@GMAIL.COM | AJ32: ANGLO | AK32: R. ALCILA GARCIA - N 252, CENTRO | AL32: CAMBORIÚ
B33: sim | E33: =SUMPRODUCT((AB33:AL33<>"")*(AB33:AL33<>"-")) -> 9 | F33: GABRIEL QUEIRÓZ WITHOFT | G33: OK | H33: TURMA 7 (TARDE) | I33: =INT((TODAY()-J33)/365.25) -> 10 | J33: 42571 | K33: 127.764.529-93 | L33: 46114 | M33: 2 | N33: PAI: 47 9 9949 8560 | O33: - | P33: - | Q33: - | R33: 46136 | S33: 46219 | T33: 46204 | U33: 46275 | V33: 46295 | AA33: 20 | AC33: OK | AD33: OK | AE33: OK | AF33: OK | AG33: 2026 | AI33: JACKSON AMARAL WITHOFT - 042.820.399-06 - JACKSON.AMARAL.IMOVEIS@GMAIL.COM | AJ33: ABALOR | AK33: R. PARANÁ N° 273, MONTE ALEGRE | AL33: CAMBORIÚ
B34: X | E34: =SUMPRODUCT((AB34:AL34<>"")*(AB34:AL34<>"-")) -> 7 | F34: GABRIEL TALES MENOTTI | G34: OK | H34: TURMA 7 (TARDE) | I34: =INT((TODAY()-J34)/365.25) -> 14 | J34: 40905 | K34: 481.045.478-95 | L34: - | M34: 2 | N34: TIA: 48 9 8441 6036 TIO: 48 9 8501 5131 | O34: 46037 | P34: 46068 | Q34: 46098 | R34: 46129 | S34: 46150 | T34: 46181 | U34: 46211 | V34: 46275 | W34: gerar boleto | X34: gerar boleto | Y34: gerar boleto | Z34: gerar boleto + jan e fev | AA34: 15 | AD34: OK | AE34: OK | AH34: B+ | AI34: FABIO VOCCARO DE CARVALHO - 045.784.399-33 - FABINHOVCX@GMAIL.COM | AJ34: ANGLO | AK34: R. LEOPOLDO LEITE - N 81, CENTRO | AL34: CAMBORIÚ
E35: =SUMPRODUCT((AB35:AL35<>"")*(AB35:AL35<>"-")) -> 6 | F35: GIORGIO BERNARDI CADORE | G35: OK | H35: TURMA 2 (MANHÃ) | I35: =INT((TODAY()-J35)/365.25) -> 8 | J35: 43123 | K35: 138.989.789-31 | L35: 46255 | M35: 2 | N35: 47984800201 | O35: - | P35: - | Q35: - | R35: - | S35: - | T35: - | U35: - | V35: 46255 | W35: 46255 | X35: 46255 | Y35: 46255 | Z35: 21/08/2026 + JANEIRO | AA35: - | AB35: 2026 | AC35: OK | AD35: OK | AE35: OK | AF35: OK | AG35: 2026
E36: =SUMPRODUCT((AB36:AL36<>"")*(AB36:AL36<>"-")) -> 7 | F36: GUILHERME DERETTI | G36: OK | H36: TURMA 2 (MANHÃ) | I36: =INT((TODAY()-J36)/365.25) -> 9 | J36: 42725 | K36: 130.381.629-65 | L36: - | N36: 47 9916-1292 | O36: - | P36: - | Q36: - | R36: - | S36: - | T36: - | U36: - | V36: 46258 | W36: 46295 | AA36: 20 | AB36: 2026 | AC36: OK | AD36: ok | AE36: ok | AF36: OK | AG36: 2026 | AH36: A+
B37: X | E37: =SUMPRODUCT((AB37:AL37<>"")*(AB37:AL37<>"-")) -> 9 | F37: GUILHERME PEREIRA DOS SANTOS | G37: OK | H37: TURMA 5 (MANHÃ) | I37: =INT((TODAY()-J37)/365.25) -> 13 | J37: 41247 | K37: 137.234.839-50 | L37: - | M37: 4 | N37: MÃE: 47 999574884 PAI: 47 99957883 | O37: 46051 | P37: 46081 | Q37: 46113 | R37: 46113 | S37: 46175 | T37: 46204 | U37: 46231 | V37: 46253 | W37: 46304 | X37: 46304 | AA37: 20 | AC37: OK | AD37: ok | AE37: OK | AG37: 2026 | AH37: O+ | AI37: GIOVANI CARVALHO DOS SANTOS - 040.639.229-36 - GIOVANICARVALHO4558@GMAIL.COM | AJ37: IVO SILVEIRA | AK37: R. MONTE PAMIR - 199, CONDE | AL37: CAMBORIÚ
B38: X | E38: =SUMPRODUCT((AB38:AL38<>"")*(AB38:AL38<>"-")) -> 11 | F38: GUSTAVO KENJI DA SILVEIRA | G38: OK | H38: TURMA 7 (TARDE) | I38: =INT((TODAY()-J38)/365.25) -> 7 | J38: 43508 | K38: 147.792.789-10 | L38: - | M38: 4 | N38: MAE:47992000766 PAI:47991877070 | O38: - | P38: 46055 | Q38: 46090 | R38: 46119 | S38: 46161 | T38: 46184 | U38: 46213 | V38: 46246 | W38: 46276 | AA38: 15 | AB38: 2026 | AC38: OK | AD38: OK | AE38: OK | AF38: UNIMED | AG38: 2026 | AH38: A+ | AI38: OTAVIO ROCHA-045.887.999-16 - OTSOCHA@GMAIL.COM | AJ38: COC | AK38: RUA ANGELIN 39- TABOLEIRO | AL38: CAMBORIÚ
B39: X | E39: =SUMPRODUCT((AB39:AL39<>"")*(AB39:AL39<>"-")) -> 8 | F39: HENRI CARPENEDO DOS SANTOS | G39: OK | H39: TURMA 2 (MANHÃ) | I39: =INT((TODAY()-J39)/365.25) -> 8 | J39: 43109 | K39: 138.485.599-86 | L39: - | M39: 2 | N39: MÃE: 47 9 9966 4883 PAI: 47 9 9900 5951 | O39: - | P39: - | Q39: 46096 | R39: 46184 | S39: 46184 | T39: 46055 | U39: 46218 | V39: 46254 | W39: 46293 | AA39: 10 | AB39: 2026 | AD39: OK | AF39: OK | AG39: 2026 | AI39: MELINA CARPENEDO - 011.665.520-80 - MELCARPENEDO@GMAIL.COM | AJ39: VEREADORES SANTA | AK39: R. GUARAPARIM - N° 130, 508/4, TABULEIRO | AL39: CAMBORIÚ
E40: =SUMPRODUCT((AB40:AL40<>"")*(AB40:AL40<>"-")) -> 7 | F40: HENRIQUE LOTTI | G40: OK | H40: TURMA 2 (MANHÃ) | I40: =INT((TODAY()-J40)/365.25) -> 8 | J40: 43164 | K40: 140.225.779-16 | L40: 46238 | M40: 3 | N40: 47 8487-5727 | O40: - | P40: - | Q40: - | R40: - | S40: - | T40: - | U40: - | V40: 46238 | W40: 46280 | AA40: 5 | AD40: OK | AE40: OK | AG40: 2026 | AI40: KETLIN LENHARDT LOTTI - 079.241.399-74 | AJ40: CECAM | AK40: R. MASSARANDUBA 553, APTO 302 | AL40: CAMBORIÚ
...

Sheet OUT
E1: CAIXA ESCOLINHA OUTUBRO 2026
A2: DATA | B2: ENTRADA | C2: SAÍDA | D2: TIPO | E2: REFERÊNCIA | F2: TIPO
A3: 46300 | B3: 300 | D3: PIX | E3: MIGUEL CORREIA - MENSALIDADE | F3: MENSALIDADE | G3: TOTAL DE ENTRADA | H3: TOTAL DE SAÍDA | I3: FATURAMENTO MENSAL
A4: 46300 | B4: 350 | D4: PIX | E4: ARTHUR HINCKEL DALLAGNO - MENSALIDADE SETEMBRO | F4: MENSALIDADE | G4: =SUM(B3:B50) -> 4437 | H4: =SUM(C3:C42) -> 0 | I4: =G4-H4 -> 4437
A5: 46301 | B5: 350 | D5: PIX | E5: HIROYUKI - MENSALIDADE | F5: MENSALIDADE
A6: 46302 | B6: 332 | D6: DÉBITO | E6: DAVI E SARA FONSECA BEUTING - MENSALIDADE | F6: MENSALIDADE
A7: 46303 | B7: 230 | D7: PIX | E7: LUCAS FERNANDO DELAGNELLO - MENSALIDADE | F7: MENSALIDADE
A8: 46303 | B8: 85 | D8: DINHEIRO | E8: BERNARDO BUENO DE ALBURQUERQUE - CALÇÃO E MEIÃO | F8: UNIFORME
A9: 46303 | B9: 225 | D9: DINHEIRO | E9: BERNARDO BUENO DE ALBURQUERQUE - MENSALIDADE | F9: MENSALIDADE
A10: 46303 | B10: 250 | D10: PIX | E10: DANIEL ELIAS - MENSALIDADE SETEMBRO | F10: MENSALIDADE
A11: 46304 | B11: 250 | D11: DINHEIRO | E11: JOHN ADAMS - MENSALIDADE | F11: MENSALIDADE
A12: 46304 | B12: 65 | D12: CREDITO | E12: JOHN ADAMS - CALÇÃO | F12: UNIFORME
A13: 46304 | B13: 140 | D13: DÉBITO | E13: JOÃO GERGENSLEY LAGUERRE - MENSALIDADE | F13: MENSALIDADE
A14: 46304 | B14: 110 | D14: DINHEIRO | E14: JOÃO GERGENSLEY LAGUERRE - MENSALIDADE | F14: MENSALIDADE
A15: 46304 | B15: 350 | D15: PIX | E15: GUILHERME PEREIRA DOS SANTOS - MENSALIDADE SETEMBRO | F15: MENSALIDADE
A16: 46304 | B16: 350 | D16: PIX | E16: GUILHERME PEREIRA DOS SANTOS - MENSALIDADE OUTUBRO | F16: MENSALIDADE
... A20: 46308 | B20: 250 | D20: PIX | E20: CICERO DE CASTRO DAPIEVE - MENSALIDADE OUTUBRO | F20: MENSALIDADE
G28: UNIFORMES: | H28: =SUM(B28,B40,B44) -> 0
G29: MENSALIDADES: | H29: =SUM(B3:B15,B17:B20,B23:B27,B29:B33,B35:B39,B42:B43,B45:B48) -> 4087
G30: OUTROS: | H30: =SUM(B22,B21,B16,B34,B41) -> 350
G32: TOTAL | H32: =SUM(H28:H30) -> 4437

Sheet DEVEDORES
A1: =SUMPRODUCT((X1:AG1<>"")*(X1:AG1<>"-")) -> 10 | B1: ANTONIO BLANCO GARCIA ROSA | C1: OK | D1: TURMA 2 (MANHÃ) | E1: =INT((TODAY()-F1)/365.25) -> 12 | F1: 41831 | G1: 047.286.990-64 | H1: 46051 | I1: 2 | J1: MÃE: 47 9 9243 5719 PAI: 47 9 9249 9441 | K1: - | L1: 46063 | M1: 46097 | N1: ESTÁ DESEMPREGADO, VAI TENTAR PAGAR | S1: IRÁ RETORNAR APENAS QUANDO PAGAR | W1: 10 | X1: 45539 | Y1: 45602 | Z1: ok | AA1: OK | AB1: OK | AC1: 01/01/2025 | AD1: O+ | AE1: JAQUELINE FLORES BLANCO - 899.584.030-72 - JAQUE_BLANCO@YAHOO.COM.BR | AF1: ARTUR SICHMANN | AG1: R. JOAQUIM AGOSTINHO VIEIRA - N 800, CENTRO | AH1: CAMBORIÚ
B5: Aluno | C5: Meses em aberto | D5: Qtd. meses | E5: Valor por mês (R$) | F5: Total devido (R$) | G5: Status | H5: Data da cobrança | I5: Observações
B6: Antonio Blanco Garcia Rosa | C6: Maio, Junho, Julho, Agosto | D6: 4 | G6: EM ABERTO | I6: ALUNO NÃO VEIO MAIS, PAI NÃO RESPONDE
B7: Davi de Souza Seben | C7: Julho, Agosto | D7: 2 | G7: FALTA 50,00 | I7: MÃE FRATUROU O PÉ (PAGAM EM DINHEIRO)
B8: Gabriel Queiróz Withoft | C8: Agosto | D8: 1 | G8: EM ABERTO | I8: VAI PAGAR SEMANA Q VEM (cobrar 08/09)
B9: Kaleb Felipe | C9: Abril, Maio, Junho, Julho, Agosto | D9: 5 | G9: EM ABERTO | I9: DIZ QUE ESTÁ EM UMA SITUAÇÃO DIFICIL E JÁ PAGOU ABRIL E MAIO (MAS NÃO TEM COMPROVANTE)
B10: João Victor Micheletti Rohrs | C10: Agosto | D10: 1 | G10: EM ABERTO | I10: Diz que virá fazer o pagamento

Sheet Observação
A1: MICHAEL NUNES BARBOSA | C1: MÃE: 47 99919 8226 PAI: 47 99993 9400 | P1: 12 | Q1: OK | R1: 8459161 | T1: 45672 | U1: OK | V1: OK | W1: --- | X1: 3° TRI 2024 | Y1: --- | Z1: 42335 | AA1: 2 | AB1: ROSILENI COSTA NUNES BARBOSA - 069.778.099-65 - MKCABECEIRAS@HOTMAIL.COM | AC1: SALESIANO | AD1: R. BERLIM - 115, SANTA REGINA
A2: OTÁVIO AUGUSTUS TONIOLO | C2: MÃE: 47 99638 1225 PAI: 41 99877 0608 | P2: 10 | Q2: OK | R2: 132.149.629-06 | S2: ok | U2: OK | V2: --- | W2: -- | X2: AT DE FREQUENCIA | Y2: --- | Z2: 42803 | AA2: 2 | AB2: D' PERUT BEAUTY EIRELI - 39611288/0001-76 - debysab@hotmail.com | AC2: CECAN | AD2: AV. RESINDO PAVAN - N 3177, ESTALEIRO
A3: JOSEP BONK BUSNELLO | C3: MÃE: 47 99999 8967 PAI: 47 99962 9402 | P3: 24 | Q3: OK | R3: 122.257.609-00 | S3: 45484 | T3: 45484 | V3: OK | W3: OK | X3: 2025 1 | Y3: O+ | Z3: 41824 | AA3: 4 | AB3: SIMONE ISABEL BONK BUSNELLO - 024.277.949-29 - ADVBONKBUSNELLO@GMAIL.COM | AC3: COC | AD3: R. 1926 - N 489, CENTRO
Y4: 42484 | Z4: 2 | AA4: MAURI A. GARCIA - 036.883.919-26 - MENDESGONCALVESLUCAS.@GMAIL.COM | AB4: DOMINGOS FONSECA | AC4: TEREZA EVANGELISTA GONÇALVES - 398, TABOLEIRO
A6: Pedir documenação começar pelo debaixo
A7: KALEB FELIPE | B7: 7
A8: DAVI LUCAS ZANELLA TONESER | B8: 6
A9: EDUARDO JOSÉ VAZ DE LIMA | B9: 6
A10: HENRI CARPENEDO DOS SANTOS | B10: 6
A11: HIROYUKI MOTA TUKAMOTO | B11: 6
A12: LEONARDO DAVI PEREIRA ROGAL | B12: 6
A13: MIGUEL CORREIA DE FREITAS | B13: 6
A14: NICOLLAS HIAN ALVES MARTINS | B14: 6
A15: AYLA G. MELLO SHFFNAN | B15: 5
A16: GABRIEL OSÓRIO GUEDES | B16: 5
A17: PEDRO DAVI LOCH | B17: 5
A18: PIETRO RIFFEL COUTO | B18: 5
... A25: LORENZO PERONIO ZAMBELE | B25: 0
A29: Avisar que estamos cancelando o Lep App
A30: PEDRO KREHNKE DE OLIVEIRA
A31: JOAO PEDRO MENEZES KNECHTEL
A32: MIGUEL PACHECO DO NASCIMENTO
A33: GABRIEL TALES MENOTTI
A34: DAVI DE SOUZA SEBEN
A35: HIROYUKI MOTA TUKAMOTO
A36: CARLOS PYETRO MATOS DE SOUZA
A37: ANTONIO BLANCO GARCIA ROSA
A38: JOHN ADAMS NERVARD
A39: JOÃO VICTOR MICHELETTI ROHRS

Sheet JUSTIFICATIVA DE FALTA
A2: NOME | B2: TURMA | C2: DATA | D2: CPF | E2: MOTIVO | G2: NOME | H2: TURMA | I2: DATA | J2: CPF | K2: MOTIVO
A3: THOMAS GERALDO DO CARMO | C3: 46256 | E3: MACHUCOU O PÉ, TEM ATESTADO DE 7 DIAS | G3: THOMAS GERALDO DO CARMO | I3: 46273 | K3: Thomas acordou com bastante dor barriga não vai conseguir treinar hoje

Sheet RETORNOS
A1: BERNARDO MARTINS DIETRICH BUENO | C1: MÃE: 47 9 9609 2686 PAI: 47 9 9782 8988 | D1: s | P1: 31 | Q1: OK | R1: 136.724.859-00 | S1: 45623 | T1: OK | U1: OK | V1: OK | W1: OK | X1: 2025 1 | Y1: O+ | Z1: 42264 | AA1: 2 | AB1: ISABELE CRISTINA DIETRICH - 056.494.439-47 - BELDIETRICH26@GMAIL.COM | AC1: DOMINGOS FONSECA | AD1: R. CEREJEIRA - N 957, TABULEIRO
A2: THOMAS GERALDO DO CARMO | B2: MÃE:47 999415473 PAI:47 996116633 | H2: 10 | I2: OK | J2: 053.034.669-90 | K2: 45729 | M2: OK | N2: OK | O2: OK | P2: 2025 1 | Q2: O- | R2: 42919 | S2: 4 | T2: AMARILDO HENRIQUE FRANCISCO - 053.034.669-90 - HENNRIQUE.CHICO@GMAIL.COM | U2: NEI PÃO E MEL | V2: R. MONTE BONETE - N 400, MONTE ALEGRE

Sheet DESATIVADOS
B1: NOME
B2: HENRY MACHADO LEIVAS | D2: 45714
C3: VENCIMENTO | D3: RG | E3: RESIDÊNCIA | F3: ATESTADO | G3: VACINAÇÃO | H3: SUS | I3: BOLETIM | J3: TIPO SANGUÍNEO | K3: NASCIMENTO | L3: ELETROCARDIOGRAMA | M3: DIAS | N3: FICHA
C4: 5 - 300 | D4: 86185985004 | K4: 40093 | M4: 4 | N4: OK
C5: DADOS FISCAIS: CLAUDIA FERNANDA DA SILVA MACHADO - 909.058.570-20 - CBELLA77@YAHOO.COM.BR
B6: LUIZ GUILHERME DA SILVA | C6: 45674 | D6: 45706
C7: VENCIMENTO | D7: RG | E7: RESIDÊNCIA | F7: ATESTADO | G7: VACINAÇÃO | H7: SUS | I7: BOLETIM | J7: TIPO SANGUÍNEO | K7: NASCIMENTO | L7: ELETROCARDIOGRAMA | M7: DIAS | N7: FICHA
C8: 15 | D8: 13396135903 | E8: OK | G8: OK | H8: OK | I8: 3° TRI 2024 | K8: 42898 | M8: 3 | N8: OK
C9: DADOS FISCAIS: LUIZ CARLOS DA SILVA - 895.988.739-00 - SILVAKLUIS@GMAIL.COM
B10: VITOR HICHMEH (MUDOU DE ESTADO) | C10: 45698 | D10: 45733 | E10: 45762
C11: VENCIMENTO | D11: RG | E11: RESIDÊNCIA | F11: ATESTADO | G11: VACINAÇÃO | H11: SUS | I11: BOLETIM | J11: TIPO SANGUÍNEO | K11: NASCIMENTO | L11: ELETROCARDIOGRAMA | M11: DIAS | N11: FICHA
C12: 10 - 250 | D12: 12605923916* | F12: 45496 | G12: OK | K12: 42472 | L12: 45496 | M12: 3 | N12: OK
C13: DADOS FISCAIS: VINICIUS SALEH HICHMEH - 053.267.069-89 - KELE_LEAL@YAHOO.COM.BR
B14: VICENZO VITORINO BANDEIRA FRANCO Encerrei porque não tive retorno da direção, senti desatenção e desigualdade no valor pago em relação às aulas | C14: 45671 | D14: 45698 | E14: 45727 | F14: 45755 | G14: 45785
C15: VENCIMENTO | D15: RG | E15: RESIDÊNCIA | F15: ATESTADO | G15: VACINAÇÃO | H15: SUS | I15: BOLETIM | J15: TIPO SANGUÍNEO | K15: NASCIMENTO | L15: ELETROCARDIOGRAMA | M15: DIAS | N15: FICHA
C16: 15 | D16: 12198734974 | E16: OK | J16: AB+ | K16: 41686 | M16: 2 | N16: OK
C17: DADOS FISCAIS: ANTONIO CARLOS BANDEIRA FRANCO - 088.833.478-89 - BANDEIRA@BANDEIRAFRANCO.COM.BR
B18: GABRIEL THIBES FILHO | C18: -------- | D18: 45706
C19: VENCIMENTO | D19: RG | E19: RESIDÊNCIA | F19: ATESTADO | G19: VACINAÇÃO | H19: SUS | I19: BOLETIM | J19: TIPO SANGUÍNEO | K19: NASCIMENTO | L19: ELETROCARDIOGRAMA | M19: DIAS | N19: FICHA
C20: 5 | D20: 11676695923 | E20: OK | F20: 45705 | J20: A+ | K20: 41906 | M20: 2 | N20: OK
C21: DADOS FISCAIS: GABRIEL THIBES - 058.802.369-86 - GABRIELTHIBES89@GMAIL.COM
B22: LUCAS COLETTO ROLIM | D22: 45708 | E22: 45708 | F22: 45708 | G22: 45708 | H22: 45708 | I22: 45708 | P22: UNIFICADO
C23: VENCIMENTO | D23: RG | E23: RESIDÊNCIA | F23: ATESTADO | G23: VACINAÇÃO | H23: SUS | I23: BOLETIM | J23: TIPO SANGUÍNEO | K23: NASCIMENTO | L23: ELETROCARDIOGRAMA | M23: DIAS | N23: FICHA | O23: MÃE: 47 9 9156 7250
C24: 5 | D24: 8048065 | F24: 45699 | K24: 41024 | L24: 45685 | M24: 2 | N24: OK | O24: PAI: 47 9 9117 8217 | P24: ENDEREÇO:
C25: DADOS FISCAIS: DANIELE FORTES COLETTO - 930.875.000-20 - | P25: R. 3130 - 112, CENTRO
C26: ------- | D26: -------- | E26: -------- | F26: 45764 | G26: 45824
C27: VENCIMENTO | D27: RG | E27: RESIDÊNCIA | F27: ATESTADO | G27: VACINAÇÃO | H27: SUS | I27: BOLETIM | J27: TIPO SANGUÍNEO | K27: NASCIMENTO | L27: ELETROCARDIOGRAMA | M27: DIAS | N27: FICHA | O27: MÃE: 43 99606 8677 | P27: ANGLO
C28: 10 | D28: 8475844 | E28: OK | G28: OK | H28: NÃO TEM | J28: O+ | K28: 42529 | L28: 45757 | M28: 2 | N28: OK | O28: PAI: 44 92003 7409
B29: RAFAEL MORAIS SETÚBAL (MUDOU DE ESTADO) | C29: DADOS FISCAIS: RAONI PEREIRA FONSECA SILVA SETÚBAL - 002.630.721-93 - RAONI.TRB@GMAIL.COM
B30: JOÃO PAULO DE OLIVEIRA PAVAN (MUDOU DE ESTADO) | C30: 45674 | D30: 45756 | E30: 45770 | P30: ANGLO
C31: VENCIMENTO | D31: RG | E31: RESIDÊNCIA | F31: ATESTADO | G31: VACINAÇÃO | H31: SUS | I31: BOLETIM | J31: TIPO SANGUÍNEO | K31: NASCIMENTO | L31: ELETROCARDIOGRAMA | M31: DIAS | N31: FICHA | O31: MÃE: 47 99653 0400
C32: 20 | D32: 12590446969 | E32: OK | H32: --- | I32: 3° TRI 2024 | K32: 42416 | M32: 3 | N32: OK | O32: PAI: 47 99668 6503 | P32: ENDEREÇO:
C33: DADOS FISCAIS: PAULIANA FERREIRA DE OLIVEIRA - 960.071.761-34 - PAULIANAPAVAN@GMAIL.COM | P33: R. 951 - N 41, CENTRO
B34: BERNARDO CAVALHEIRODE MEDEIROS RIBEIRO (valor da mensalidade) | E34: 45715 | F34: 45755 | P34: CLOTILDE
C35: VENCIMENTO | D35: CPF | E35: RESIDÊNCIA | F35: ATESTADO | G35: VACINAÇÃO | H35: SUS | I35: BOLETIM | J35: TIPO SANGUÍNEO | K35: NASCIMENTO | L35: ELETROCARDIOGRAMA | M35: DIAS | N35: FICHA | O35: MÃE: 47 9 9723 0613
C36: 5 | D36: 61.294.650-92 | E36: OK | G36: OK | H36: OK | K36: 43479 | M36: 2 | N36: OK | O36: PAI: 47 9 8800 5989 | P36: ENDEREÇO
C37: DADOS FISCAIS: MATHEUS DE MEDEIROS - 019.476.320-00 - MEDEIROS220214@GMAIL.COM | P37: R. AMAZONAS - N 19, CENTRO
B38: BRAYAN KUSSEK MULLER | C38: -------- | D38: -------- | E38: -------- | F38: 45748 | G38: 45783
C39: VENCIMENTO | D39: RG | E39: RESIDÊNCIA | F39: ATESTADO | G39: VACINAÇÃO | H39: SUS | I39: BOLETIM | J39: TIPO SANGUÍNEO | K39: NASCIMENTO | L39: ELETROCARDIOGRAMA | M39: DIAS | N39: FICHA
C40: 5 | D40: 8117047 | E40: OK | F40: 45742 | G40: OK | H40: OK | I40: ATESTADO DE FREQUENCIA | J40: O+ | K40: 41870 | M40: 2 | N40: OK
...

Sheet ANUAL
A1: MÊS | B1: ENTRADA MENSAL | C1: SAÍDA MENSAL | D1: FATURAMENTO MENSAL
A2: JANEIRO | B2: =SUM(JAN!B2:B65) -> 9180 | C2: =SUM(JAN!C2:C65) -> 0 | D2: =B2-C2 -> 9180
A3: FEVEREIRO | B3: =SUM(FEV!B3:B62) -> 3007 | C3: =SUM(FEV!C3:C62) -> 0 | D3: =B3-C3 -> 3007
A4: MARÇO | B4: =SUM(MAR!B3:B63) -> 4080 | C4: =SUM(MAR!C3:C63) -> 0 | D4: =B4-C4 -> 4080
A5: ABRIL | B5: =SUM(ABR!B3:B64) -> 4206.5 | C5: =SUM(ABR!C3:C64) -> 0 | D5: =B5-C5 -> 4206.5
A6: MAIO | B6: =SUM(MAI!B3:B65) -> 9702.5 | C6: =SUM(MAI!C3:C65) -> 0 | D6: =B6-C6 -> 9702.5
A7: JUNHO | B7: =SUM(JUN!B3:B66) -> 8412 | C7: =SUM(JUN!C3:C66) -> 0 | D7: =B7-C7 -> 8412
A8: JULHO | B8: =SUM(JUL!B3:B67) -> 15122 | C8: =SUM(JUL!C3:C67) -> 0 | D8: =B8-C8 -> 15122
A9: AGOSTO | B9: =SUM(AGO!B4:B70) -> 18186 | C9: =SUM(AGO!C4:C70) -> 0 | D9: =B9-C9 -> 18186
A10: SETEMBRO | B10: =SUM(SET!B3:B72) -> 20017 | C10: =SUM(SET!C3:C72) -> 0 | D10: =B10-C10 -> 20017
A11: OUTUBRO | D11: =B11-C11 -> 0
A12: NOVEMBRO | D12: =B12-C12 -> 0
A13: DEZEMBRO | D13: =B13-C13 -> 0
A14: ANO | B14: =SUM(B2:B13) -> 91913 | C14: =SUM(C1:C13) -> 0 | D14: =SUM(D2:D13) -> 91913

Sheet MAI
E1: CAIXA ESCOLINHA MAIO 2026
A2: DATA: | B2: ENTRADA: | C2: SAÍDA: | D2: TIPO: | E2: REFERÊNCIA: | F2: Coluna 1 | G2: TOTAL DE ENTRADA | H2: TOTAL DE SAÍDA | I2: FATURAMENTO MENSAL
A3: 46146 | B3: 230 | D3: CRÉDITO 4X | E3: UNIFORME ADRIAN DE BAIRROS | F3: UNIFORME | G3: =SUM(B2:B41) -> 9702.5 | H3: =SUM(C2:C41) -> 0 | I3: =G3-H3 -> 9702.5
A4: 46147 | B4: 40 | D4: PIX | E4: MEIÃO 28-32 AZUL | F4: UNIFORME
A5: 46147 | B5: 300 | D5: PIX | E5: LUCAS MENEGUSSO PEREIRA DA ROCHA - MARÇO MENSALIDADE | F5: MENSALIDADE
A6: 46149 | B6: 350 | D6: PIX | E6: PIETRO RIFFEL COUTO - MENSALIDADE MAIO | F6: MENSALIDADE
A7: 46149 | B7: 65 | D7: CRÉDITO A VISTA | E7: CALÇÃO | F7: UNIFORME
A8: 46150 | B8: 300 | D8: PIX | E8: YAN CHISTOPHER MACHADO PEREIRA - MENSALIDADE ABRIL | F8: MENSALIDADE
A9: 46153 | B9: 332.5 | D9: DÉBITO | E9: DAVI FONSECA BEUTING - MENSALIDADE MAIO | F9: MENSALIDADE
A10: 46154 | B10: 230 | D10: DINHEIRO | E10: JOHN ADAMS NERVARD - MENSALIDADE MAIO | F10: MENSALIDADE
A11: 46160 | B11: 280 | D11: CRÉDITO | E11: MIGUEL CORREIA DE FREITAS - MENSALIDADE ABRIL | F11: MENSALIDADE
A12: 46160 | B12: 180 | D12: CRÉDITO | F12: MENSALIDADE
A13: 46161 | B13: 330 | D13: PIX | E13: GUSTAVO KENJI DA SILVEIRA - MENSALIDADE MAIO | F13: MENSALIDADE
A14: 46161 | B14: 250 | D14: PIX | E14: DAVI PEREIRA - MENSALIDADE MAIO | F14: MENSALIDADE
A15: 46163 | B15: 250 | D15: PIX | E15: BENTO GHENO GONÇALVES - MENSALIDADE ABRIL | F15: MENSALIDADE
A16: 46163 | B16: 140 | D16: PIX | E16: CAMISETA - 684 | F16: UNIFORME
A17: 46163 | B17: 3780 | D17: CREDITO 12X | E17: DAVI MARQUES DA SILVA E VICENTE MARQUES DA SILVA - ANUAL MENSALIDADE | F17: MENSALIDADE
A18: 46163 | B18: 990 | D18: CRÉDITO 3X | E18: GABRIEL OSÓRIO - MAIO, JUNHO E JULHO MENSALIDADE | F18: MENSALIDADE
A19: 46163 | B19: 300 | D19: PIX | E19: DAVI LUCAS ZANELLA TONESER - MENSALIDADE MAIO | F19: MENSALIDADE
A20: 46164 | B20: 65 | D20: PIX | E20: JOSEP - CALÇÃO GG
A21: 46170 | B21: 240 | D21: PIX | E21: UNIFORME MIGUEL PACHECO - CALÇÃO G E CAMISA 692 | F21: UNIFORME
A22: 46170 | B22: 250 | D22: PIX | E22: GABRIEL COELHO - MENSALIDADE | F22: MENSALIDADE
A23: 46171 | B23: 250 | D23: DINHEIRO | E23: JOÃO GERGENSLEY LAGUERRE - MENSALIDADE ABRIL | F23: MENSALIDADE
A24: 46154 | B24: 250 | D24: PIX | E24: DAVI LUCIANO DOMINICIANO - MENSALIDADE
A25: 46165 | B25: 300 | D25: PIX | E25: MIGUEL PACHECO DO NASCIMENTO - MENSALIDADE MAIO | F25: MENSALIDADE

Sheet JUN
E1: CAIXA ESCOLINHA JUNHO 2026
A2: DATA: | B2: ENTRADA: | C2: SAÍDA: | D2: TIPO: | E2: REFERÊNCIA: | F2: TIPO
A3: 46175 | B3: 350 | D3: PIX | E3: GUILHERME PEREIRA DOS SANTOS - MENSALIDADE MAIO | F3: MENSALIDADE | H3: TOTAL DE ENTRADA | I3: TOTAL DE SAÍDA | J3: FATURAMENTO MENSAL
A4: 46178 | B4: 220 | D4: DINHEIRO | E4: PEDRO HENRIQUE LIMA DA SILVA - MENSALIDADE JUNHO RETORNOU DO ATESTADO | F4: MENSALIDADE | H4: =SUM(B3:B42) -> 8412 | I4: =SUM(C3:C42) -> 0 | J4: =H4-I4 -> 8412
A5: 46182 | B5: 180 | D5: PIX | E5: DAVI LUCIANO DOMINICIANO - MENSALIDADE JUNHO | F5: MENSALIDADE
A6: 46184 | B6: 330 | D6: PIX | E6: GUSTAVO KENJI DA SILVEIRA - MENSALIDADE JUNHO | F6: MENSALIDADE
A7: 46184 | B7: 200 | D7: PIX | E7: HENRI CARPENEDO DOS SANTOS - MENSALIDADE ABRIL | F7: MENSALIDADE
A8: 46184 | B8: 200 | D8: PIX | E8: HENRI CARPENEDO DOS SANTOS - MENSALIDADE MAIO | F8: MENSALIDADE
A9: 46188 | B9: 500 | D9: PIX | E9: PEDRO HENRIQUE BELICA GASPAR - MENSALIDADE MAIO E JUNHO | F9: MENSALIDADE
A10: 46192 | B10: 280 | D10: PIX | E10: EMANUEL SIMAS MACHADO - MENSALIDADE ABRIL | F10: MENSALIDADE
A11: 46195 | B11: 280 | D11: CRÉDITO | E11: MIGUEL CORREIA DE FREITAS - MENSALIDADE DE MAIO | F11: MENSALIDADE
A12: 46188 | B12: 332 | D12: DINHEIRO | E12: SARA E DAVI FONSECA - MENSALIDADE DE JUNHO | F12: MENSALIDADE
A13: 46195 | B13: 350 | D13: PIX | E13: Pietro Riffel Couto - MENSALIDADE JUNHO | F13: MENSALIDADE
A14: 46195 | B14: 300 | D14: PIX | E14: Lucas Menegusso Pereira Da Rocha - MENSALIDADE ABRIL | F14: MENSALIDADE
A15: 46195 | B15: 250 | D15: PIX | E15: Davi Lucas Zanella Tonezer - MENSALIDADE JUNHO | F15: MENSALIDADE
A16: 46195 | B16: 250 | D16: PIX | E16: MICHAEL NUNES BARBOSA - MENSALIDADE ABRIL | F16: MENSALIDADE
... A32: 46199 | B32: 350 | D32: PIX | E32: ARTHUR HINCKEL DALLAGNO - MENSALIDADE JUNHO | F32: MENSALIDADE
A33: 46199 | D33: PIX | E33: CARLOS PYETRO MATOS DE SOUZA - MENSALIDADE MAIO | F33: MENSALIDADE
A34: 46199 | B34: 250 | D34: PIX | E34: LORENZO PERONIO ZAMBELE - MENSALIDADE MAIO | F34: MENSALIDADE
A35: 46199 | B35: 250 | D35: PIX | E35: MARTIN PERONIO ZAMBELE - MENSALIDADE MAIO | F35: MENSALIDADE
A36: 46199 | B36: 250 | D36: PIX | E36: LORENZO PERONIO ZAMBELE - MENSALIDADE JUNHO | F36: MENSALIDADE
A37: 46199 | B37: 250 | D37: PIX | E37: MARTIN PERONIO ZAMBELE - MENSALIDADE JUNHO | F37: MENSALIDADE

Sheet JUL
E1: CAIXA ESCOLINHA JULHO 2026
A2: DATA | B2: ENTRADA | C2: SAÍDA | D2: TIPO | E2: REFERÊNCIA | F2: TIPO
A3: 46204 | B3: 300 | D3: PIX | E3: DAVI DE SOUZA SEBEN - MENSALIDADE MAIO | F3: MENSALIDADE | G3: TOTAL DE ENTRADA | H3: TOTAL DE SAÍDA | I3: FATURAMENTO MENSAL
A4: 46204 | B4: 300 | D4: PIX | E4: DAVI DE SOUZA SEBEN - MENSALIDADE JUNHO | F4: MENSALIDADE | G4: =SUM(B3:B50) -> 12587 | H4: =SUM(C3:C42) -> 0 | I4: =G4-H4 -> 12587
A5: 46204 | B5: 300 | D5: PIX | E5: MICHAEL NUNES BARBOSA - MENSALIDADE MAIO | F5: MENSALIDADE
A6: 46204 | B6: 300 | D6: PIX | E6: MICHAEL NUNES BARBOSA - MENSALIDADE JUNHO | F6: MENSALIDADE
A7: 46147 | B7: 250 | D7: PIX | E7: EDUARDO PEDRO BOM CORDEIRO - MENSALIDADE MAIO | F7: MENSALIDADE
A8: 46204 | B8: 250 | D8: PIX | E8: GABRIEL QUEIROZ WITHOFT - MENSALIDADE JUNHO | F8: MENSALIDADE
A9: 46204 | B9: 350 | D9: PIX | E9: GUILHERME PEREIRA DOS SANTOS - MENSALIDADE JUNHO | F9: MENSALIDADE
A10: 46205 | B10: 200 | D10: PIX | E10: HENRI CARPENEDO DOS SANTOS - MENSALIDADE JUNHO | F10: MENSALIDADE
A11: 46206 | B11: 250 | D11: PIX | E11: EDUARDO PEDRO BOM CORDEIRO - MENSALIDADE ABRIL | F11: MENSALIDADE
A12: 46209 | B12: 180 | D12: PIX | E12: ANTÔNIO SALVADOR - MENSALIDADE JUNHO | F12: MENSALIDADE
A13: 46209 | B13: 250 | D13: PIX | E13: PEDRO HENRIQUE BELICA GASPAR | F13: MENSALIDADE
A14: 46211 | B14: 320 | D14: DINHEIRO | E14: ISABELLA MARIA PINHEIRO - MENSALIDADE JULHO E AGOSTO | F14: MENSALIDADE
A15: 46212 | B15: 230 | D15: DINHEIRO | E15: JOHN ADAMS NERVARD - MENSALIDADE JULHO | F15: MENSALIDADE
A16: 46212 | B16: 25 | D16: PIX | E16: LUCAS GABRIEL DA SILVA CORDEIRO - GARRAFINHA | F16: OUTROS
... A27: 46217 | B27: 350 | D27: PIX | E27: PEDRO DAVI LOCH - MENSALIDADE | F27: MENSALIDADE
A28: 46217 | B28: 230 | D28: PIX | E28: PEDRO DAVI LOCH - UNIFORME | F28: UNIFORME | G28: UNIFORMES: | H28: =SUM(B28,B40,B44) -> 860
A29: 46217 | B29: 180 | D29: BOLETO | E29: LEONARDO DAVI PEREIRA ROGAL - MENSALIDADE JULHO | F29: MENSALIDADE | G29: MENSALIDADES: | H29: =SUM(B3:B15,B17:B20,B23:B27,B29:B33,B35:B39,B42:B43,B45:B48) -> 10682
A30: 46218 | B30: 200 | D30: PIX | E30: HENRI CARPENEDO DOS SANTOS - MENSALIDADE JULHO | F30: MENSALIDADE | G30: OUTROS: | H30: =SUM(B22,B21,B16,B34,B41) -> 545
A31: 46218 | B31: 300 | D31: PIX | E31: YAN CHISTOPHER MACHADO PEREIRA - MENSALIDADE JULHO | F31: MENSALIDADE
A32: 46218 | B32: 250 | D32: PIX | E32: BENTO GHENO GONÇALVES - MENSALIDADE JULHO | F32: MENSALIDADE | G32: TOTAL | H32: =SUM(H28:H30) -> 12087
A33: 46218 | B33: 270 | D33: PIX | E33: ISACK CABRAL FINOTTI - Mensalidade Julho | F33: MENSALIDADE
A34: 46219 | B34: 25 | D34: CREDITO | E34: BENTO GHENO GONÇALVES - GARRAFINHA | F34: OUTROS
A35: 46219 | B35: 250 | D35: PIX | E35: GABRIEL QUEIRÓZ WITHOFT - MENSALIDADE MAIO | F35: MENSALIDADE
A36: 46189 | B36: 300 | D36: PIX | E36: LUCAS MENEGUSSO PEREIRA DA ROCHA - MENSALIDADE JUNHO | F36: MENSALIDADE
A37: 46189 | B37: 300 | D37: PIX | E37: LUCAS MENEGUSSO PEREIRA DA ROCHA - MENSALIDADE JULHO | F37: MENSALIDADE
A38: 46219 | B38: 350 | D38: PIX | E38: JOAO PEDRO MENEZES KNECHTEL - MENSALIDADE JUNHO | F38: MENSALIDADE
A39: 46219 | B39: 350 | D39: PIX | E39: JOAO PEDRO MENEZES KNECHTEL - MENSALIDADE JULHO | F39: MENSALIDADE
A40: 46220 | B40: 230 | D40: PIX | E40: Anthony Carvalho - Uniforme | F40: UNIFORME
A41: 46220 | B41: 25 | D41: PIX | E41: Anthony Carvalho - Garrafinha | F41: OUTROS
A42: 46220 | B42: 225 | D42: DINHEIRO | E42: CARLOS PYETRO MATOS DE SOUZA - MENSALIDADE JUNHO | F42: MENSALIDADE
A43: 46220 | B43: 350 | D43: PIX | E43: GULHERME HINCKEL DALLAGNO - MENSALIDADE MAIO | F43: MENSALIDADE
A44: 46220 | B44: 400 | D44: CREDITO 3X | E44: PIETRO E MIGUEL SCHIAVON - UNIFORMES | F44: UNIFORME
... A58: 46234 | B58: 230 | D58: PIX | E58: UNIFORME RYAN CARLOS | F58: UNIFORME

Sheet AGO
A2: DATA: | B2: ENTRADA: | C2: SAÍDA: | D2: TIPO: | E2: REFERÊNCIA: | F2: TIPO
A3: 46237 | B3: 170 | D3: DINHEIRO | E3: LUCAS EVANGELISTA DE SOUZA - MENSALIDADE DE JULHO | F3: MENSALIDADE | H3: TOTAL DE ENTRADA | I3: TOTAL DE SAÍDA | J3: FATURAMENTO MENSAL
A4: 46237 | B4: 170 | D4: DINHEIRO | E4: LUCAS EVANGELISTA DE SOUZA - MENSALIDADE DE AGOSTO | F4: MENSALIDADE | H4: =SUM(B3:B51) -> 17401 | I4: =SUM(C3:C43) -> 0 | J4: =H4-I4 -> 17401
A5: 46237 | B5: 225 | D5: DÉBITO | E5: RAJI GHAITH - MENSALIDADE AGOSTO | F5: MENSALIDADE
A6: 46237 | B6: 275 | D6: DÉBITO | E6: RAYAN GHAITH - MENSALIDADE AGOSTO | F6: MENSALIDADE
A7: 46237 | B7: 350 | D7: DÉBITO | E7: RAYAN E RAJI GHAITH - UNIFORMES | F7: UNIFORME
A8: 46238 | B8: 270 | D8: DINHEIRO | E8: HENRIQUE LOTTI - MENSALIDADE | F8: MENSALIDADE
A9: 46238 | B9: 230 | D9: PIX | E9: Lucas Fernando Delagnello - MENSALIDADE | F9: MENSALIDADE
A10: 46240 | B10: 140 | D10: CREDITO | E10: ISACK CABRAL FINOTTI - UNIFORME | F10: UNIFORME
A11: 46240 | B11: 900 | D11: CRÉDITO 3X | E11: GABRIEL OSÓRIO GUEDES - MENSALIDADE JULHO - OUTUBRO | F11: MENSALIDADE
A12: 46240 | B12: 195 | D12: CRÉDITO | E12: MIGUEL STOLFI - UNIFORME - CAMISETA E CALÇÃO | F12: UNIFORME
A13: 46240 | B13: 280 | D13: PIX | E13: EMANUEL SIMAS MACHADO - JUNHO | F13: MENSALIDADE
A14: 46241 | B14: 140 | D14: CREDITO | E14: BRYAN BELICA GASPAR - UNIFORME | F14: UNIFORME
A15: 46241 | B15: 350 | D15: PIX | E15: HIROYUKI MOTA TUKAMOTO - MENSALIDADE AGOSTO | F15: MENSALIDADE
A16: 46244 | B16: 180 | D16: PIX | E16: ANTÔNIO SALVADOR - MENSALIDADE AGOSTO | F16: MENSALIDADE
... A51: 46290 | B51: 225 | D51: DINHEIRO | E51: JOSÉ JOAQUIN YUNIS - MENSALIDADE | F51: MENSALIDADE
A52: 46290 | D52: CREDITO | E52: ATHUR SIMAS - UNIFORME | F52: UNIFORME
A53: 46290 | D53: DINHEIRO | E53: ARTHUR SIMAS - MENSALIDADE | F53: MENSALIDADE
A54: 46261 | B54: 230 | D54: PIX | E54: UNIFORME - ENZO | F54: UNIFORME
A55: 46262 | B55: 225 | D55: DINHEIRO | E55: CARLOS PYETRO MATOS DE SOUZA - MENSALIDADE AGOSTO | F55: MENSALIDADE
A56: 46246 | B56: 300 | D56: PIX | E56: PEDRO KRENKHE - MENSALIDADE | F56: MENSALIDADE
A57: 46254 | B57: 200 | D57: PIX | E57: HENRI CARPENEDO | F57: MENSALIDADE

Sheet SET
E1: CAIXA ESCOLINHA SETEMBRO 2026
A2: DATA | B2: ENTRADA | C2: SAÍDA | D2: TIPO | E2: REFERÊNCIA | F2: TIPO
A3: 46266 | B3: 250 | D3: CREDITO | E3: DAVI GOMES SILVEIRA - MENSALIDADE | F3: MENSALIDADE | G3: TOTAL DE ENTRADA | H3: TOTAL DE SAÍDA | I3: FATURAMENTO MENSAL
A4: 46266 | B4: 230 | D4: CREDITO | E4: UNIFORME JOSÉ JOAQUIM | F4: UNIFORME | G4: =SUM(B3:B50) -> 17859 | H4: =SUM(C3:C42) -> 0 | I4: =G4-H4 -> 17859
A5: 46266 | B5: 185 | D5: PIX | E5: GUSTAVO KENJI - CAMISA JOGO E CAMISA UNIFORME | F5: UNIFORME
A6: 46268 | B6: 250 | D6: PIX | E6: RICARDO TERESKOVAC - MENSALIDADE | F6: MENSALIDADE
A7: 46268 | B7: 250 | D7: PIX | E7: EDUARDO PEDRO BOM CORDEIRO - MENSALIDADE | F7: MENSALIDADE
A8: 46268 | B8: 700 | D8: PIX | E8: GULHERME E ARTHUR HINCKEL DALLAGNO - JULHO | F8: MENSALIDADE
A9: 46268 | B9: 225 | D9: DINHEIRO | E9: LORENZO DOS SANTOS DE OLIVEIRA- MENSALIDADE | F9: MENSALIDADE
A10: 46268 | B10: 200 | D10: DINHEIRO | E10: LORENZO DOS SANTOS DE OLIVEIRA - UNIFORME | F10: UNIFORME
A11: 46269 | B11: 200 | D11: DINHEIRO | E11: GIORGIO - UNIFORME | F11: UNIFORME
A12: 46269 | B12: 300 | D12: DÉBITO | E12: PEDRO KRENK - MENSALIDADE | F12: MENSALIDADE
A13: 46269 | B13: 270 | D13: DINHEIRO | E13: ANTHONY GABRIEL DA SILVA - MENSALIDADE | F13: MENSALIDADE
A14: 46273 | B14: 315 | D14: DINHEIRO | E14: ARTHUR VALENDORFF DE CARVALHO - MNESALIDADE | F14: MENSALIDADE
A15: 46273 | B15: 250 | D15: PIX | E15: Antônio Jacotto Neto - MENSALIDADE | F15: MENSALIDADE
A16: 46273 | B16: 250 | D16: PIX | E16: CICERO DE CASTRO DAPIEVE - MENSALIDADE | F16: MENSALIDADE
... A27: 46279 | B27: 250 | D27: PIX | E27: MIGUEL YUTA KANAI - MENSALIDADE | F27: MENSALIDADE
A28: 46279 | B28: 475 | D28: PIX | E28: AYLA E DAVI FIDENCIO - DIVIDA MENS. JULHO | F28: MENSALIDADE | G28: UNIFORMES: | H28: =SUM(B28,B40,B44) -> 860
A29: 46279 | B29: 350 | D29: CRÉDITO | E29: MIGUEL STOLFI - MENSALIDADE | F29: MENSALIDADE | G29: MENSALIDADES: | H29: =SUM(B3:B15,B17:B20,B23:B27,B29:B33,B35:B39,B42:B43,B45:B48) -> 14301
A30: 46279 | B30: 332 | D30: DÉBITO | E30: DAVI FONSECA BEUTING - MENSALIDADE | F30: MENSALIDADE | G30: OUTROS: | H30: =SUM(B22,B21,B16,B34,B41) -> 943
A31: 46280 | B31: 230 | D31: DINHEIRO | E31: JOHN ADAMS - MENSALIDADE | F31: MENSALIDADE
A32: 46280 | B32: 400 | D32: DINHEIRO | E32: DAVI SEBEN - MENSALIDADE JULHO E AGOSTO | F32: MENSALIDADE | G32: TOTAL | H32: =SUM(H28:H30) -> 16104
A33: 46280 | B33: 475 | D33: PIX | E33: AYLA E DAVI FIDENCIO - MENS. SETEMBRO | F33: MENSALIDADE
A34: 46280 | B34: 45 | D34: PIX | E34: ARTHUR HINCKEL - MEIÃO | F34: UNIFORME
A35: 46273 | B35: 250 | D35: PIX | E35: CICERO DE CASTRO DAPIEVE - MENSALIDADE | F35: MENSALIDADE
A36: 46273 | B36: 250 | D36: PIX | E36: ANTÔNIO JACOTTO NETO - MENSALIDADE | F36: MENSALIDADE
A37: 46280 | B37: 230 | D37: DINHEIRO | E37: PEDRO HENRIQUE LIMA DA SILVA - MENSALIDADE | F37: MENSALIDADE
A38: 46282 | B38: 65 | D38: CREDITO | E38: THOMAS GERALDO - CALÇÃO UNIFORME | F38: UNIFORME
A39: 46282 | B39: 500 | D39: CREDITO | E39: RAJI E RAYAN GHAITH - MENSALIDADE | F39: MENSALIDADE
A40: 46283 | B40: 180 | D40: PIX | E40: BRAYAN BELICA DALMOLIN - mensalidade | F40: MENSALIDADE
A41: 46283 | B41: 280 | D41: CREDITO | E41: MIGUEL CORREIA DE FREITAS - MENSALIDADE | F41: MENSALIDADE
A42: 46286 | B42: 162 | D42: DINHEIRO | E42: LUCAS EVANGELISTA - MENSALIDADE | F42: MENSALIDADE
A43: 46286 | B43: 180 | D43: Pix | E43: ANTÔNIO SALVADOR SOARES - Mensalidade | F43: MENSALIDADE
A44: 46283 | B44: 205 | D44: CREDITO | E44: MIGUEL YUTA - UNIFORME CALÇÃO E CAMISA | F44: UNIFORME
A45: 46288 | E45: YAN CHISTOPHER MACHADO PEREIRA | F45: MENSALIDADE
A46: 46289 | B46: 500 | D46: CREDITO | E46: MARTIN E LORENZO PERONIO | F46: MENSALIDADE
A47: 46286 | B47: 3402 | D47: CREDITO 12X | E47: JOSÉ MIGUEL DA SILVA - MENS 12 MESES | F47: MENSALIDADE
A48: 46293 | B48: 200 | D48: PIX | E48: HENRI CARPENEDO DOS SANTOS - MENSALIDADE SET | F48: MENSALIDADE
A49: 46290 | B49: 45 | D49: DEBITO | E49: SARA FONSECA - UNIFORME MEIAO | F49: UNIFORME
A50: 46294 | B50: 1710 | D50: CREDITO 6X | E50: DOM MENSALIDADE 6 MESES | F50: MENSALIDADE
...

Sheet DEZ
E1: CAIXA ESCOLINHA NOVEMBRO- 2025
A2: DATA | B2: ENTRADA | C2: SAÍDA | D2: TIPO | E2: ALUNO | F2: CPF | G2: TOTAL DE ENTRADA | H2: TOTAL DE SAÍDA | I2: FATURAMENTO MENSAL
G5: =SUM(B2:B43) -> 0 | H5: =SUM(C5:C43) -> 0 | I5: =G5-H5 -> 0

Sheet NOV
E1: CAIXA ESCOLINHA NOVEMBRO- 2025
A2: DATA | B2: ENTRADA | C2: SAÍDA | D2: TIPO | E2: ALUNO | F2: CPF | G2: TOTAL DE ENTRADA | H2: TOTAL DE SAÍDA | I2: FATURAMENTO MENSAL
G3: =SUM(B2:B41) -> 0 | H3: =SUM(C3:C41) -> 0 | I3: =G3-H3 -> 0

Sheet ABR
E1: CAIXA ESCOLINHA ABRIL 2026
A2: DATA | B2: ENTRADA | C2: SAÍDA | D2: TIPO | E2: REFERÊNCIA | G2: TOTAL DE ENTRADA | H2: TOTAL DE SAÍDA | I2: FATURAMENTO MENSAL
A3: 46126 | B3: 350 | D3: PIX | E3: JOÃO PEDRO MENEZES KNETCHEL - MENSALIDADE ABRIL | G3: =SUM(B2:B41) -> 4206.5 | H3: =SUM(C2:C41) -> 0 | I3: =G3-H3 -> 4206.5
A4: 46135 | B4: 300 | D4: PIX | E4: DAVI LUCAS ZANELLA TONESER - MENSALIDADE ABRIL
A5: 46135 | B5: 140 | D5: DÉBITO | E5: JOHN ADAMS NERVARD - CAMISETA 673
A6: 46122 | B6: 250 | D6: PIX | E6: PEDRO HENRIQUE BELICA GASPAR - MENSALIDADE ABRIL
A7: 46136 | B7: 250 | D7: PIX | E7: GABRIEL QUEIRÓZ WITHOFT - MENSALIDADE ABRIL
A8: 46139 | B8: 285 | D8: CRÉDITO 2X | E8: MIGUEL CORREIA DE FREITAS - MENSALIDADE MARÇO
A9: 46140 | B9: 140 | D9: DÉBITO | E9: CAMISETA GOLEIRO TAM 10
A10: 46141 | B10: 1334 | D10: CRÉDITO 4X | E10: JOÃO VICTOR MICHELETTI ROHRS - MENSALIDADE 6 MESES
A11: 46128 | B11: 332.5 | D11: DÉBITO | E11: DAVI FONSECA BEUTING - MENSALIDADE ABRIL
A12: 46142 | B12: 475 | D12: CRÉDITO | E12: LORENZO E MARTIN PERONIO ZAMBELI - MENSALIDADE ABRIL
A13: 46119 | B13: 350 | D13: PIX | E13: GUSTAVO KENJI DA SILVEIRA - MENSALIDADE ABRIL

Sheet MAR
E1: CAIXA ESCOLINHA MARÇO 2026
A2: DATA | B2: ENTRADA | C2: SAÍDA | D2: TIPO | E2: REFERÊNCIA | G2: TOTAL DE ENTRADA | H2: TOTAL DE SAÍDA | I2: FATURAMENTO MENSAL
A3: 46090 | B3: 350 | D3: PIX | E3: MENSALIDADE JANEIRO - ARTHUR HINCKEL DALLAGNO | G3: =SUM(B2:B90) -> 4080 | H3: =SUM(C2:C51) -> 0 | I3: =G3-H3 -> 4080
A4: 46090 | B4: 350 | D4: PIX | E4: MENSALIDADE JANEIRO - GUSTAVO KENJI DA SILVEIRA
A5: 46084 | B5: 450 | D5: PIX | E5: Lucas Menegusso Pereira Da Rocha /prart Rochel/pai
A6: 46084 | B6: 180 | D6: PIX | E6: DOUGLAS BROCHIER RODRIGUES - PARTICULAR
A7: 46091 | B7: 1425,00/ 6x | C7: 420,00 uniforme | D7: cartão | E7: BENJAMIN PIOPELLI CXOSTA | F7: 6 MESES 10/03
A8: 46091 | B8: 250 | D8: pix | E8: Davi Luciano Domiciano - Particular
A9: 46091 | B9: 250 | D9: pix | E9: Davi Fidencio / Particular
A10: 46097 | B10: 250 | D10: pix | E10: Henri Carpenedo Dos Santos Particular
A11: 46105 | B11: 500 | D11: cartao | E11: Lorenzo E Martim / particular
A12: 46108 | B12: 350 | D12: pix | E12: EDUARDO PEDRO BOM CORDEIRO/ PART FERNANDA /MÃE
A13: 46093 | B13: 350 | D13: pix | E13: João Pedro Menezes Knechtel - Particular
A14: 46098 | B14: 250 | D14: pix | E14: GABRIEL TALES MENOTTI /PART
A15: 46118 | B15: 250 | D15: PIX | E15: Davi Luciano Domiciano - Particular
A16: 46125 | B16: 300

Sheet FEV
E1: CAIXA ESCOLINHA FEVEREIRO 2026
A2: DATA | B2: ENTRADA | C2: SAÍDA | D2: TIPO | E2: REFERÊNCIA | F2: TOTAL DE ENTRADA | G2: TOTAL DE SAÍDA | H2: FATURAMENTO MENSAL
A3: 46056 | B3: 312 | D3: DINHEIRO | E3: MENSALIDADE E MATRÍCULA - GUSTAVO DA ROCHA HIRT | F3: =SUM(B2:B41) -> 3007 | G3: =SUM(C2:C41) -> 0 | H3: =F3-G3 -> 3007
A4: 46056 | B4: 240 | D4: PIX | E4: UNIFORME COMPLETO
A5: 46055 | B5: 330 | D5: PIX | E5: MENSALIDADE FEVEREIRO - GUSTAVO KENJI DA SILVEIRA
A6: 46058 | B6: 250 | D6: DINHEIRO | E6: MENSALIDADE JANEIRO - JOÃO GERGENSLEY LAGUERRE
A7: 46058 | B7: 465 | D7: PIX | E7: MENSALIDADE E UNIFORME - BENTO GHENO GONÇALVES
A8: 46063 | B8: 250 | D8: PIX | E8: MENSALIDADE ANTONIO BLANCO GARCIA ROSA
A9: 46063 | B9: 230 | D9: DINHEIRO | E9: MENSALIDADE - JOHN ADAMS NERVARD
A10: 46062 | B10: 350 | D10: DINHEIRO | E10: MENSALIDADE JANEIRO - AYO MIGUEL CAMPOS DOMINGUES
A11: 46062 | B11: 350 | D11: DEBITO | E11: MENSALIDADE FEVEREIRO DAVI FONSECA
A12: 46076 | B12: 230 | D12: PIX | E12: MENSALIDADE - LUCAS DE SOUZA BARRETO

Sheet JAN
E1: CAIXA ESCOLINHA JANEIRO 2026
A2: DATA | B2: ENTRADA | C2: SAÍDA | D2: TIPO | E2: REFERÊNCIA | F2: TOTAL DE ENTRADA | G2: TOTAL DE SAÍDA | H2: FATURAMENTO MENSAL
A3: 46034 | B3: 280 | D3: PIX | E3: MENSALIDADE EMANUEL SIMAS MACHADO - NOVEMBRO 2025 | F3: =SUM(B2:B45) -> 9180 | G3: =SUM(C2:C45) -> 0 | H3: =F3-G3 -> 9180
A4: 46037 | B4: 250 | D4: DÉBITO | E4: MENSALIDADE DAVI LUCIANO
A5: 46042 | B5: 250 | D5: PIX | E5: MENSALIDADE CARLOS PYETRO - DEZEMBRO 2025
A6: 46042 | B6: 230 | D6: DINHEIRO | E6: MENSALIDADE JOHN ADAMS NERVARD - JANEIRO 2026
A7: 46042 | B7: 250 | D7: PIX | E7: MENSALIDADE PEDRO KREHNKE DE OLIVEIRA - JANEIRO
A8: 46044 | B8: 530 | D8: PIX | E8: CONJUNTO UNIFORME E MENSALIDADE - AUGUSTO GERVASONI
A9: 46045 | B9: 140 | D9: PIX | E9: CAMISETA UNIFORME - ARTHUR HINCKELL DALLAGNO
A10: 46045 | B10: 450 | D10: PIX | E10: LUCAS MENEGUSSO - PAGOU AS MENSALIDADES ATRASADAS (FALTA 450)
A11: 46045 | B11: 280 | D11: DINHEIRO | E11: MENSALIDADE MIGUEL CORREIA DE FREITAS - JANEIRO
A12: 46045 | B12: 3440 | D12: CRÉDITO 10X | E12: MENSALIDADE BERNARDO ROCHA E CAMISETA UNIFORME
A13: 46048 | B13: 280 | D13: PIX | E13: MENSALIDADE EMANUEL SIMAS MACHADO - DEZEMBRO 2025
A14: 46321 | B14: 285 | D14: DINHEIRO | E14: MENSALIDADE MIGUEL PACHECO DO NASCIMENTO - JANEIRO
A15: 46321 | B15: 230 | D15: CRÉDITO | E15: UNIFORME MIGUEL PACHECO DO NASCIMENTO - NÃO PEGOU, DEIXAR RESERVADO CALÇÃO M BLUSA G
A16: 46322 | B16: =855+180 -> 1035 | D16: CRÉDITO | E16: VITOR HICHMEH MENSALIDADE 6 MESES
A17: 46322 | B17: 140 | D17: CRÉDITO | E17: CAMISETA UNIFORME - VITOR HICHMEH
A18: 46049 | B18: 350 | D18: DÉBITO | E18: MENSALIDADE - SARA FONSECA BEUTING
A19: 46049 | B19: 180 | D19: PIX | E19: MENSALIDADE JANEIRO - DOUGLAS BROCHIER RODRIGUES
A20: 46051 | B20: 350 | D20: PIX | E20: MENSALIDADE JANEIRO - GUILHERME PEREIRA DOS SANTOS
A21: 46052 | B21: 230 | D21: CRÉDIO 3X | E21: UNIFORME COMPLETO - MIGUEL CORREIA DE FREITAS
